Workbook

Sheet Чек-лист
A1: Чек-лист
A2: id | B2: наименование
A3: Позитивные кейсы
A4: ='Тест-кейсы'!B2 -> #TC1 | B4: ='Тест-кейсы'!B4 -> Проверка работоспособности программы с корректными данными
A5: ='Тест-кейсы'!B11 -> #TC2 | B5: ='Тест-кейсы'!B13 -> Проверка работоспособности программы с пограничными значениями даты (01 и 12 месяц)
A6: ='Тест-кейсы'!B20 -> #TC3 | B6: ='Тест-кейсы'!B22 -> Проверка работоспособности программы с пограничными значениями даты (01 и 31 день)
A7: ='Тест-кейсы'!B29 -> #TC4 | B7: ='Тест-кейсы'!B31 -> Проверка работоспособности программы с пограничными значениями даты (1700 и 3010 год)
A8: ='Тест-кейсы'!B38 -> #TC5 | B8: ='Тест-кейсы'!B40 -> Проверка работоспособности программы с особенными данными ( 9999 год)
A9: ='Тест-кейсы'!B47 -> #TC6 | B9: ='Тест-кейсы'!B49 -> Проверка работоспособности программы с особенными данными (01.01.1900)
A10: ='Тест-кейсы'!B56 -> #TC7 | B10: ='Тест-кейсы'!B58 -> Проверка работоспособности программы с особенными данными ( 01.01.1970)
A11: Негативные кейсы
A12: ='Тест-кейсы'!B66 -> #TC8 | B12: ='Тест-кейсы'!B68 -> Проверка работоспособности программы с пустым вводом
A13: ='Тест-кейсы'!B75 -> #TC9 | B13: ='Тест-кейсы'!B77 -> Проверка работоспособности программы с некорректными данными (пробельные символы)
A14: ='Тест-кейсы'!B84 -> #TC10 | B14: ='Тест-кейсы'!B86 -> Проверка работоспособности программы с некорректными данными (невозможное значение даты - 99.99.9999)
A15: ='Тест-кейсы'!B93 -> #TC11 | B15: ='Тест-кейсы'!B95 -> Проверка работоспособности программы с некорректными данными (невозможное значение даты - 00.00.0000)
A16: ='Тест-кейсы'!B102 -> #TC12 | B16: ='Тест-кейсы'!B104 -> Проверка работоспособности программы с некорректными данными (невозможное значение даты - 99 дней в месяце)
A17: ='Тест-кейсы'!B111 -> #TC13 | B17: ='Тест-кейсы'!B113 -> Проверка работоспособности программы с некорректными данными (невозможное значение даты - 99 месяцев)
A18: ='Тест-кейсы'!B120 -> #TC14 | B18: ='Тест-кейсы'!B122 -> Проверка работоспособности программы с некорректными данными (невозможное значение даты - 00 день)
A19: ='Тест-кейсы'!B129 -> #TC15 | B19: ='Тест-кейсы'!B131 -> Проверка работоспособности программы с некорректными данными (невозможное значение даты - 00 месяц)
A20: ='Тест-кейсы'!B138 -> #TC16 | B20: ='Тест-кейсы'!B140 -> Проверка работоспособности программы с некорректными данными (невозможное значение даты - 0000 год)
A21: ='Тест-кейсы'!B147 -> #TC17 | B21: ='Тест-кейсы'!B149 -> Проверка работоспособности программы с одинаковыми датами.
A22: ='Тест-кейсы'!B156 -> #TC18 | B22: ='Тест-кейсы'!B158 -> Проверка работоспособности программы с некорректными данными (символы ~!@#$%^&*()_+-={}[].,?<>)
A23: ='Тест-кейсы'!B165 -> #TC19 | B23: ='Тест-кейсы'!B167 -> Проверка работоспособности программы с некорректными симолами записи даты (,-_/\|?).
A24: ='Тест-кейсы'!B174 -> #TC20 | B24: ='Тест-кейсы'!B176 -> Проверка работоспособности программы с неверным форматом ввода (кол-во цифр в записи меньше положенного)
A25: ='Тест-кейсы'!B183 -> #TC21 | B25: ='Тест-кейсы'!B185 -> Проверка работоспособности программы с неверным форматом ввода (кол-во цифр в записи больше положенного)
A26: ='Тест-кейсы'!B192 -> #TC22 | B26: ='Тест-кейсы'!B194 -> Проверка работоспособности программы с некорректными данными (отрицательные значение дней)
A27: ='Тест-кейсы'!B201 -> #TC23 | B27: ='Тест-кейсы'!B203 -> Проверка работоспособности программы с некорректными данными (отрицательные значение месяца)
A28: ='Тест-кейсы'!B210 -> #TC24 | B28: ='Тест-кейсы'!B212 -> Проверка работоспособности программы с некорректными данными (отрицательные значение года)
A29: ='Тест-кейсы'!B219 -> #TC25 | B29: ='Тест-кейсы'!B221 -> Проверка работоспособности программы с некорректными данными (32 дня в месяце)
A30: ='Тест-кейсы'!B228 -> #TC26 | B30: ='Тест-кейсы'!B230 -> Проверка работоспособности программы с некорректными данными (13 месяцев в году)
A31: ='Тест-кейсы'!B237 -> #TC27 | B31: ='Тест-кейсы'!B239 -> Проверка работоспособности программы с некорректными данными (в поле присутствуют лишние символы)
A32: ='Тест-кейсы'!B246 -> #TC28 | B32: ='Тест-кейсы'!B248 -> Проверка работоспособности программы с неполными данными (указываем одно значение даты вместо двух ожидаемых)
A33: ='Тест-кейсы'!B255 -> #TC29 | B33: ='Тест-кейсы'!B257 -> Проверка работоспособности программы с некорректными данными (первая дата больше второй)
A34: ='Тест-кейсы'!B264 -> #TC30 | B34: ='Тест-кейсы'!B266 -> Проверка работоспособности программы с неверным форматом ввода (при записи не прописываем нули)
A35: ='Тест-кейсы'!B273 -> #TC31 | B35: ='Тест-кейсы'!B275 -> Проверка работоспособности программы с некорректными данными (буквы вместо даты)

Sheet Тест-кейсы
A1: Позитивные
A2: id | B2: #TC1
A3: Приоритет | B3: Высокий
A4: Название | B4: Проверка работоспособности программы с корректными данными
A5: Предусловие | B5: Запустить исполняемый файл CALENDAR_1.1.exe
A6: Шаги воспроизведения | B6: 1. Ввести первую дату в формате d.m.y 01.01.2023 и подтвердить клавишей enter
B7: 2. Ввести вторую дату в формате d.m.y 03.01.2023 и подтвердить клавишей enter
A8: Ожидаемый результат | B8: Программа выводит случайную дату в заданном диапазоне.
A9: Фактический результат | B9: Программа выводит случайную дату в заданном диапазоне yyyy.mm.dd, плюс неизвестное пользователю числовое значение в формате XX:XX:XX.XXX
A11: id | B11: #TC2
A12: Приоритет | B12: Высокий
A13: Название | B13: Проверка работоспособности программы с пограничными значениями даты (01 и 12 месяц)
A14: Предусловие | B14: Запустить исполняемый файл CALENDAR_1.1.exe
A15: Шаги воспроизведения | B15: 1. Ввести в качестве значения месяца первой даты 01 и подтвердить клавишей enter
B16: 2. Ввести в качестве значения месяца второй даты 12 и подтвердить клавишей enter
A17: Ожидаемый результат | B17: Программа выводит случайную дату в заданном диапазоне d.m.y
A18: Фактический результат | B18: Программа выводит случайную дату в заданном диапазоне yyyy.mm.dd, плюс неизвестное пользователю числовое значение в формате XX:XX:XX.XXX
A20: id | B20: #TC3
A21: Приоритет | B21: Высокий
A22: Название | B22: Проверка работоспособности программы с пограничными значениями даты (01 и 31 день)
A23: Предусловие | B23: Запустить исполняемый файл CALENDAR_1.1.exe
A24: Шаги воспроизведения | B24: 1. Ввести в качестве значения дня первой даты 01 и подтвердить клавишей enter
B25: 2. Ввести в качестве значения дня второй даты 31 и подтвердить клавишей enter
A26: Ожидаемый результат | B26: Программа выводит случайную дату в заданном диапазоне d.m.y
A27: Фактический результат | B27: Программа выводит случайную дату в заданном диапазоне yyyy.mm.dd, плюс неизвестное пользователю числовое значение в формате XX:XX:XX.XXX
A29: id | B29: #TC4
A30: Приоритет | B30: Высокий
A31: Название | B31: Проверка работоспособности программы с пограничными значениями даты (1700 и 3010 год)
A32: Предусловие | B32: Запустить исполняемый файл CALENDAR_1.1.exe
A33: Шаги воспроизведения | B33: 1. Ввести в качестве значения года первой даты 1700 и подтвердить клавишей enter
B34: 2. Ввести в качестве значения года второй даты 3010 и подтвердить клавишей enter
A35: Ожидаемый результат | B35: Программа выводит случайную дату в заданном диапазоне d.m.y
A36: Фактический результат | B36: Программа выводит случайную дату в заданном диапазоне yyyy.mm.dd, плюс неизвестное пользователю числовое значение в формате XX:XX:XX.XXX
A38: id | B38: #TC5
A39: Приоритет | B39: Средний
A40: Название | B40: Проверка работоспособности программы с особенными данными ( 9999 год)
A41: Предусловие | B41: Запустить исполняемый файл CALENDAR_1.1.exe
A42: Шаги воспроизведения | B42: 1. Ввести в качестве значения года в первое поле 9999 и подвердить клавишей enter
B43: 2. Ввести в качестве значения года во второе поле 9999 и подвердить клавишей enter
A44: Ожидаемый результат | B44: Программа выводит случайную дату в заданном диапазоне d.m.y
...

Sheet Баг-репорты
A1: id | B1: #BR1
A2: Заголовок | B2: Неожиданное значение в приложении CALENDAR_1.1.exe при выводе результата.
A3: Описание | B3: Кроме ожидаемой даты программа выводит ещё числовое значение в формате XX:XX:XX.XXX*
A4: Шаги воспроизведения | B4: 1. Ввести первую дату в формате d.m.y 01.01.2023 и подтвердить клавишей enter
B5: 2. Ввести вторую дату в формате d.m.y 03.01.2023 и подтвердить клавишей enter
A6: Ожидаемый результат | B6: Программа выводит случайную дату в заданном диапазоне.
A7: Фактический результат | B7: Программа выводит случайную дату в заданном диапазоне yyyy.mm.dd, плюс неизвестное пользователю числовое значение в формате XX:XX:XX.XXX
A8: Приложение
A15: id | B15: #BR2
A16: Заголовок | B16: Неожиданное значение в приложении CALENDAR_1.1.exe при выводе результата.
A17: Описание | B17: Кроме ожидаемой даты программа выводит ещё числовое значение в формате XX:XX:XX.XXX*
A18: Шаги воспроизведения | B18: 1. Ввести в качестве значения месяца первой даты 01 и подтвердить клавишей enter
B19: 2. Ввести в качестве значения месяца второй даты 12 и подтвердить клавишей enter
A20: Ожидаемый результат | B20: Программа выводит случайную дату в заданном диапазоне d.m.y
A21: Фактический результат | B21: Программа выводит случайную дату в заданном диапазоне yyyy.mm.dd, плюс неизвестное пользователю числовое значение в формате XX:XX:XX.XXX
A22: Приложение
A29: id | B29: #BR3
A30: Заголовок | B30: Неожиданное значение в приложении CALENDAR_1.1.exe при выводе результата.
A31: Описание | B31: Кроме ожидаемой даты программа выводит ещё числовое значение в формате XX:XX:XX.XXX*
A32: Шаги воспроизведения | B32: 1. Ввести в качестве значения дня первой даты 01 и подтвердить клавишей enter
B33: 2. Ввести в качестве значения дня второй даты 31 и подтвердить клавишей enter
A34: Ожидаемый результат | B34: Программа выводит случайную дату в заданном диапазоне d.m.y
A35: Фактический результат | B35: Программа выводит случайную дату в заданном диапазоне yyyy.mm.dd, плюс неизвестное пользователю числовое значение в формате XX:XX:XX.XXX
A36: Приложение
A42: id | B42: #BR4
A43: Заголовок | B43: Неожиданное значение в приложении CALENDAR_1.1.exe при выводе результата.
A44: Описание | B44: Кроме ожидаемой даты программа выводит ещё числовое значение в формате XX:XX:XX.XXX*
A45: Шаги воспроизведения | B45: 1. Ввести в качестве значения года первой даты 1700 и подтвердить клавишей enter
B46: 2. Ввести в качестве значения года второй даты 3010 и подтвердить клавишей enter
A47: Ожидаемый результат | B47: Программа выводит случайную дату в заданном диапазоне d.m.y
A48: Фактический результат | B48: Программа выводит случайную дату в заданном диапазоне yyyy.mm.dd, плюс неизвестное пользователю числовое значение в формате XX:XX:XX.XXX
A49: Приложение
A55: id | B55: #BR5
A56: Заголовок | B56: Неожиданное значение в приложении CALENDAR_1.1.exe при выводе результата.
A57: Описание | B57: Кроме ожидаемой даты программа выводит ещё числовое значение в формате XX:XX:XX.XXX*
A58: Шаги воспроизведения | B58: 1. Ввести в качестве значения года в первое поле 9999 и подвердить клавишей enter
B59: 2. Ввести в качестве значения года во второе поле 9999 и подвердить клавишей enter
A60: Ожидаемый результат | B60: Программа выводит случайную дату в заданном диапазоне d.m.y
A61: Фактический результат | B61: Программа выводит случайную дату в заданном диапазоне yyyy.mm.dd, плюс неизвестное пользователю числовое значение в формате XX:XX:XX.XXX
A62: Приложение
...

Sheet Отчёт
B1: Отчет
B3: - test-case PASSED
B4: - test-case FAILED
A6: id тест-кейса | B6: наименование | D6: id баг-репорта
A7: ='Тест-кейсы'!B2 -> #TC1 | B7: ='Тест-кейсы'!B4 -> Проверка работоспособности программы с корректными данными | D7: ='Баг-репорты'!B1 -> #BR1
A8: ='Тест-кейсы'!B11 -> #TC2 | B8: ='Тест-кейсы'!B13 -> Проверка работоспособности программы с пограничными значениями даты (01 и 12 месяц) | D8: ='Баг-репорты'!B15 -> #BR2
A9: ='Тест-кейсы'!B20 -> #TC3 | B9: ='Тест-кейсы'!B22 -> Проверка работоспособности программы с пограничными значениями даты (01 и 31 день) | D9: ='Баг-репорты'!B29 -> #BR3
A10: ='Тест-кейсы'!B29 -> #TC4 | B10: ='Тест-кейсы'!B31 -> Проверка работоспособности программы с пограничными значениями даты (1700 и 3010 год) | D10: ='Баг-репорты'!B42 -> #BR4
A11: ='Тест-кейсы'!B38 -> #TC5 | B11: ='Тест-кейсы'!B40 -> Проверка работоспособности программы с особенными данными ( 9999 год) | D11: ='Баг-репорты'!B55 -> #BR5
A12: ='Тест-кейсы'!B47 -> #TC6 | B12: ='Тест-кейсы'!B49 -> Проверка работоспособности программы с особенными данными (01.01.1900) | D12: ='Баг-репорты'!B70 -> #BR6
A13: ='Тест-кейсы'!B56 -> #TC7 | B13: ='Тест-кейсы'!B58 -> Проверка работоспособности программы с особенными данными ( 01.01.1970) | D13: ='Баг-репорты'!B85 -> #BR7
A14: ='Тест-кейсы'!B66 -> #TC8 | B14: ='Тест-кейсы'!B68 -> Проверка работоспособности программы с пустым вводом
A15: ='Тест-кейсы'!B75 -> #TC9 | B15: ='Тест-кейсы'!B77 -> Проверка работоспособности программы с некорректными данными (пробельные символы)
A16: ='Тест-кейсы'!B84 -> #TC10 | B16: ='Тест-кейсы'!B86 -> Проверка работоспособности программы с некорректными данными (невозможное значение даты - 99.99.9999)
A17: ='Тест-кейсы'!B93 -> #TC11 | B17: ='Тест-кейсы'!B95 -> Проверка работоспособности программы с некорректными данными (невозможное значение даты - 00.00.0000)
A18: ='Тест-кейсы'!B102 -> #TC12 | B18: ='Тест-кейсы'!B104 -> Проверка работоспособности программы с некорректными данными (невозможное значение даты - 99 дней в месяце)
A19: ='Тест-кейсы'!B111 -> #TC13 | B19: ='Тест-кейсы'!B113 -> Проверка работоспособности программы с некорректными данными (невозможное значение даты - 99 месяцев)
A20: ='Тест-кейсы'!B120 -> #TC14 | B20: ='Тест-кейсы'!B122 -> Проверка работоспособности программы с некорректными данными (невозможное значение даты - 00 день)
A21: ='Тест-кейсы'!B129 -> #TC15 | B21: ='Тест-кейсы'!B131 -> Проверка работоспособности программы с некорректными данными (невозможное значение даты - 00 месяц)
A22: ='Тест-кейсы'!B138 -> #TC16 | B22: ='Тест-кейсы'!B140 -> Проверка работоспособности программы с некорректными данными (невозможное значение даты - 0000 год)
A23: ='Тест-кейсы'!B147 -> #TC17 | B23: ='Тест-кейсы'!B149 -> Проверка работоспособности программы с одинаковыми датами. | D23: ='Баг-репорты'!B99 -> #BR8
A24: ='Тест-кейсы'!B156 -> #TC18 | B24: ='Тест-кейсы'!B158 -> Проверка работоспособности программы с некорректными данными (символы ~!@#$%^&*()_+-={}[].,?<>)
A25: ='Тест-кейсы'!B165 -> #TC19 | B25: ='Тест-кейсы'!B167 -> Проверка работоспособности программы с некорректными симолами записи даты (,-_/\|?).
A26: ='Тест-кейсы'!B174 -> #TC20 | B26: ='Тест-кейсы'!B176 -> Проверка работоспособности программы с неверным форматом ввода (кол-во цифр в записи меньше положенного)
A27: ='Тест-кейсы'!B183 -> #TC21 | B27: ='Тест-кейсы'!B185 -> Проверка работоспособности программы с неверным форматом ввода (кол-во цифр в записи больше положенного)
A28: ='Тест-кейсы'!B192 -> #TC22 | B28: ='Тест-кейсы'!B194 -> Проверка работоспособности программы с некорректными данными (отрицательные значение дней)
A29: ='Тест-кейсы'!B201 -> #TC23 | B29: ='Тест-кейсы'!B203 -> Проверка работоспособности программы с некорректными данными (отрицательные значение месяца)
A30: ='Тест-кейсы'!B210 -> #TC24 | B30: ='Тест-кейсы'!B212 -> Проверка работоспособности программы с некорректными данными (отрицательные значение года)
A31: ='Тест-кейсы'!B219 -> #TC25 | B31: ='Тест-кейсы'!B221 -> Проверка работоспособности программы с некорректными данными (32 дня в месяце)
A32: ='Тест-кейсы'!B228 -> #TC26 | B32: ='Тест-кейсы'!B230 -> Проверка работоспособности программы с некорректными данными (13 месяцев в году)
A33: ='Тест-кейсы'!B237 -> #TC27 | B33: ='Тест-кейсы'!B239 -> Проверка работоспособности программы с некорректными данными (в поле присутствуют лишние символы)
A34: ='Тест-кейсы'!B246 -> #TC28 | B34: ='Тест-кейсы'!B248 -> Проверка работоспособности программы с неполными данными (указываем одно значение даты вместо двух ожидаемых)
A35: ='Тест-кейсы'!B255 -> #TC29 | B35: ='Тест-кейсы'!B257 -> Проверка работоспособности программы с некорректными данными (первая дата больше второй)
A36: ='Тест-кейсы'!B264 -> #TC30 | B36: ='Тест-кейсы'!B266 -> Проверка работоспособности программы с неверным форматом ввода (при записи не прописываем нули)
A37: ='Тест-кейсы'!B273 -> #TC31 | B37: ='Тест-кейсы'!B275 -> Проверка работоспособности программы с некорректными данными (буквы вместо даты)
A40: PASSED | B40: 23
A41: FAILED | B41: 8
A42: BLOCKED | B42: 0
B45: * - программа постоянно выводит числовое значение в формате XX:XX:XX.XXX, если это отображение времени, то оно имеет неверный формат т.к. количество часов больше 24. Необходима документация.
